Workbook

Sheet Instructions
A2: 1. General Instructions
A3: Do not modify the structure of this Excel file.
A4: Offeror shall only enter data in the green-shaded cells on the "Detailed Price" tab. All other cells and tabs have calculated fields or contain data entered by FDIC.
A7: 2. "Detailed Price" Tab
A8: This tab is organized by contract period and requests charges for Base, Option Period 1, and Option Period 2, and Option Period 3.
A9: Column A: Select the applicable Option Period (note that TO Option Periods 1 & 2 will cross multiple Option Periods).
A10: Column B: Enter applicable labor category.
A11: Column D: Enter the proposed number of hours.
A12: Column E: Enter the proposed rates.
A13: Column G: Offeror input not required. Calculates the charges for each resource based on preceding columns.
A15: 3. "Summary Price" Tab
A16: This tab does not require Offeror input. It displays the summary charges for each TO period.
A18: The FDIC will compute an overall evaluated price (OEP) using the Offerors proposed hourly rates. This computation will be for evaluation purposes only.

Sheet Detailed Price
A1: Data Modernization Section Support - Detailed Pricing
A4: Transition Period: 12/1/2025 - 12/31/2025
A5: Period | B5: Labor Category | D5: Hours | E5: Hourly Rate | F5: Discount Rate | G5: Extended Price
A6: Transition | C6: =CONCATENATE(A6,B6) -> Transition | G6: =SUM(D6*E6) -> 0
A7: Transition | C7: =CONCATENATE(A7,B7) -> Transition | G7: =SUM(D7*E7) -> 0
A8: Transition | C8: =CONCATENATE(A8,B8) -> Transition | G8: =SUM(D8*E8) -> 0
A9: Transition | C9: =CONCATENATE(A9,B9) -> Transition | G9: =SUM(D9*E9) -> 0
A10: Transition | C10: =CONCATENATE(A10,B10) -> Transition | G10: =SUM(D10*E10) -> 0
A11: Transition | C11: =CONCATENATE(A11,B11) -> Transition | G11: =SUM(D11*E11) -> 0
A12: Transition | C12: =CONCATENATE(A12,B12) -> Transition | G12: =SUM(D12*E12) -> 0
A13: Transition | C13: =CONCATENATE(A13,B13) -> Transition | G13: =SUM(D13*E13) -> 0
A14: Transition | C14: =CONCATENATE(A14,B14) -> Transition | G14: =SUM(D14*E14) -> 0
A15: Transition | C15: =CONCATENATE(A15,B15) -> Transition | G15: =SUM(D15*E15) -> 0
F16: TO Base Total | G16: =SUM(G6:G15) -> 0
A18: Base Period: 1/1/2026 - 12/31/2026
A19: Period | B19: Labor Category | D19: Hours | E19: Hourly Rate | F19: Discount Rate | G19: Extended Price
A20: Base | C20: =CONCATENATE(A20,B20) -> Base | G20: =SUM(D20*E20) -> 0
A21: Base | C21: =CONCATENATE(A21,B21) -> Base | G21: =SUM(D21*E21) -> 0
A22: Base | C22: =CONCATENATE(A22,B22) -> Base | G22: =SUM(D22*E22) -> 0
A23: Base | C23: =CONCATENATE(A23,B23) -> Base | G23: =SUM(D23*E23) -> 0
A24: Base | C24: =CONCATENATE(A24,B24) -> Base | G24: =SUM(D24*E24) -> 0
A25: Base | C25: =CONCATENATE(A25,B25) -> Base | G25: =SUM(D25*E25) -> 0
A26: Base | C26: =CONCATENATE(A26,B26) -> Base | G26: =SUM(D26*E26) -> 0
A27: Base | C27: =CONCATENATE(A27,B27) -> Base | G27: =SUM(D27*E27) -> 0
A28: Base | C28: =CONCATENATE(A28,B28) -> Base | G28: =SUM(D28*E28) -> 0
A29: Base | C29: =CONCATENATE(A29,B29) -> Base | G29: =SUM(D29*E29) -> 0
F30: TO Base Total | G30: =SUM(G20:G29) -> 0
A32: Option Period 1: 1/1/2027 - 12/31/2027
A33: Period | B33: Labor Category | D33: Hours | E33: Hourly Rate | F33: Discount Rate | G33: Extended Price
A34: OP1 | C34: =CONCATENATE(A34,B34) -> OP1 | G34: =SUM(D34*E34) -> 0
A35: OP1 | C35: =CONCATENATE(A35,B35) -> OP1 | G35: =SUM(D35*E35) -> 0
A36: OP1 | C36: =CONCATENATE(A36,B36) -> OP1 | G36: =SUM(D36*E36) -> 0
A37: OP1 | C37: =CONCATENATE(A37,B37) -> OP1 | G37: =SUM(D37*E37) -> 0
A38: OP1 | C38: =CONCATENATE(A38,B38) -> OP1 | G38: =SUM(D38*E38) -> 0
A39: OP1 | C39: =CONCATENATE(A39,B39) -> OP1 | G39: =SUM(D39*E39) -> 0
A40: OP1 | C40: =CONCATENATE(A40,B40) -> OP1 | G40: =SUM(D40*E40) -> 0
A41: OP1 | C41: =CONCATENATE(A41,B41) -> OP1 | G41: =SUM(D41*E41) -> 0
A42: OP1 | C42: =CONCATENATE(A42,B42) -> OP1 | G42: =SUM(D42*E42) -> 0
A43: OP1 | C43: =CONCATENATE(A43,B43) -> OP1 | G43: =SUM(D43*E43) -> 0
A44: OP1 | C44: =CONCATENATE(A44,B44) -> OP1 | G44: =SUM(D44*E44) -> 0
...

Sheet Summary Price
B1: Data Modernization Section Support - Summary Pricing
B3: Period | C3: TO Period | D3: Dates | E3: Extended Price
B4: Transition | C4: Transition | D4: 12/1/2025 - 12/31/2025 | E4: =SUM('Detailed Price'!G16) -> 0
B5: Base | C5: Base Period | D5: 1/1/2026 - 12/31/2026 | E5: =SUM('Detailed Price'!G30) -> 0
B6: OP1 | C6: Option Period 1 | D6: 1/1/2027 - 12/31/2027 | E6: =SUM('Detailed Price'!G49) -> 0
B7: OP2 | C7: Option Period 2 | D7: 1/1/2028 - 12/31/2028 | E7: =SUM('Detailed Price'!G68) -> 0
B8: OP3 | C8: Option Period 3 | D8: 1/1/2029 - 12/31/2029 | E8: =SUM('Detailed Price'!G88) -> 0
D9: Total Charges | E9: =SUM(E4:E8) -> 0
